Traceback (most recent call last):
  File "e:/文档/赛博世界/main.py", line 249, in <module>
    main()
  File "e:/文档/赛博世界/main.py", line 242, in main
    game()
  File "e:/文档/赛博世界/main.py", line 137, in game
    r = function.battle(data,id,bool(is_escaped))
  File "e:\文档\赛博世界\function.py", line 337, in battle
    for i in projection:
RuntimeError: dictionary changed size during iteration
